{"uuid": "2eb3fc33-c444-479f-b5d3-6138bc22513b", "children": ["528f7224-1958-445d-ad5a-4e30e4a073ca"], "befores": [{"name": "browser", "status": "broken", "statusDetails": {"message": "RuntimeError: 浏览器启动失败: Message: session not created: probably user data directory is already in use, please specify a unique value for --user-data-dir argument, or don't use --user-data-dir\nStacktrace:\n\tGetHandleVerifier [0x0xd0ba83+63395]\n\tGetHandleVerifier [0x0xd0bac4+63460]\n\t(No symbol) [0x0xb52113]\n\t(No symbol) [0x0xb858b8]\n\t(No symbol) [0x0xb811a9]\n\t(No symbol) [0x0xbcae57]\n\t(No symbol) [0x0xbca74a]\n\t(No symbol) [0x0xbbf1a6]\n\t(No symbol) [0x0xb8e7b2]\n\t(No symbol) [0x0xb8f654]\n\tGetHandleVerifier [0x0xf88883+2672035]\n\tGetHandleVerifier [0x0xf83cba+2652634]\n\tGetHandleVerifier [0x0xd32bca+223466]\n\tGetHandleVerifier [0x0xd22cb8+158168]\n\tGetHandleVerifier [0x0xd2978d+185517]\n\tGetHandleVerifier [0x0xd13b78+96408]\n\tGetHandleVerifier [0x0xd13d02+96802]\n\tGetHandleVerifier [0x0xcfe90a+9770]\n\tBaseThreadInitThunk [0x0x76ff5d49+25]\n\tRtlInitializeExceptionChain [0x0x7786d1ab+107]\n\tRtlGetAppContainerNamedObjectPath [0x0x7786d131+561]\n\n", "trace": "  File \"D:\\Python312-32\\Lib\\site-packages\\pluggy\\_callers.py\", line 167, in _multicall\n    teardown.throw(outcome._exception)\n  File \"D:\\Python312-32\\Lib\\site-packages\\pytest_asyncio\\plugin.py\", line 681, in pytest_fixture_setup\n    return (yield)\n            ^^^^^\n  File \"D:\\Python312-32\\Lib\\site-packages\\pluggy\\_callers.py\", line 167, in _multicall\n    teardown.throw(outcome._exception)\n  File \"D:\\Python312-32\\Lib\\site-packages\\_pytest\\setuponly.py\", line 36, in pytest_fixture_setup\n    return (yield)\n            ^^^^^\n  File \"D:\\Python312-32\\Lib\\site-packages\\pluggy\\_callers.py\", line 103, in _multicall\n    res = hook_impl.function(*args)\n          ^^^^^^^^^^^^^^^^^^^^^^^^^\n  File \"D:\\Python312-32\\Lib\\site-packages\\_pytest\\fixtures.py\", line 1140, in pytest_fixture_setup\n    result = call_fixture_func(fixturefunc, request, kwargs)\n             ^^^^^^^^^^^^^^^^^^^^^^^^^^^^^^^^^^^^^^^^^^^^^^^\n  File \"D:\\Python312-32\\Lib\\site-packages\\_pytest\\fixtures.py\", line 891, in call_fixture_func\n    fixture_result = next(generator)\n                     ^^^^^^^^^^^^^^^\n  File \"D:\\project_selenium_improve\\tests\\conftest.py\", line 7, in browser\n    driver = browser.start_browser()\n             ^^^^^^^^^^^^^^^^^^^^^^^\n  File \"D:\\project_selenium_improve\\core\\browser_manager.py\", line 108, in start_browser\n    raise RuntimeError(f\"浏览器启动失败: {str(e)}\")\n"}, "start": 1754633086004, "stop": 1754633103452}], "start": 1754633086004, "stop": 1754633103560}