{"uuid": "8b189818-6612-49de-9614-2929824ef4a2", "children": ["22a77b23-20ae-4b66-980f-f42e633ce051"], "befores": [{"name": "browser", "status": "broken", "statusDetails": {"message": "RuntimeError: 浏览器启动失败: Message: session not created: probably user data directory is already in use, please specify a unique value for --user-data-dir argument, or don't use --user-data-dir\nStacktrace:\n\tGetHandleVerifier [0x0xe4fd23+62915]\n\tGetHandleVerifier [0x0xe4fd64+62980]\n\t(No symbol) [0x0xc83e13]\n\t(No symbol) [0x0xcb78e8]\n\t(No symbol) [0x0xcb31e9]\n\t(No symbol) [0x0xcfce32]\n\t(No symbol) [0x0xcfc74a]\n\t(No symbol) [0x0xcf11d6]\n\t(No symbol) [0x0xcc0833]\n\t(No symbol) [0x0xcc16a4]\n\tGetHandleVerifier [0x0x10b8d13+2590131]\n\tGetHandleVerifier [0x0x10b3f5a+2570234]\n\tGetHandleVerifier [0x0xe759da+217722]\n\tGetHandleVerifier [0x0xe66048+153832]\n\tGetHandleVerifier [0x0xe6c4ad+179533]\n\tGetHandleVerifier [0x0xe57728+94152]\n\tGetHandleVerifier [0x0xe578b2+94546]\n\tGetHandleVerifier [0x0xe42bca+9322]\n\tBaseThreadInitThunk [0x0x752c5d49+25]\n\tRtlInitializeExceptionChain [0x0x771cd1ab+107]\n\tRtlGetAppContainerNamedObjectPath [0x0x771cd131+561]\n\n", "trace": "  File \"D:\\Python312-32\\Lib\\site-packages\\pluggy\\_callers.py\", line 167, in _multicall\n    teardown.throw(outcome._exception)\n  File \"D:\\Python312-32\\Lib\\site-packages\\pytest_asyncio\\plugin.py\", line 681, in pytest_fixture_setup\n    return (yield)\n            ^^^^^\n  File \"D:\\Python312-32\\Lib\\site-packages\\pluggy\\_callers.py\", line 167, in _multicall\n    teardown.throw(outcome._exception)\n  File \"D:\\Python312-32\\Lib\\site-packages\\_pytest\\setuponly.py\", line 36, in pytest_fixture_setup\n    return (yield)\n            ^^^^^\n  File \"D:\\Python312-32\\Lib\\site-packages\\pluggy\\_callers.py\", line 103, in _multicall\n    res = hook_impl.function(*args)\n          ^^^^^^^^^^^^^^^^^^^^^^^^^\n  File \"D:\\Python312-32\\Lib\\site-packages\\_pytest\\fixtures.py\", line 1140, in pytest_fixture_setup\n    result = call_fixture_func(fixturefunc, request, kwargs)\n             ^^^^^^^^^^^^^^^^^^^^^^^^^^^^^^^^^^^^^^^^^^^^^^^\n  File \"D:\\Python312-32\\Lib\\site-packages\\_pytest\\fixtures.py\", line 891, in call_fixture_func\n    fixture_result = next(generator)\n                     ^^^^^^^^^^^^^^^\n  File \"D:\\project_selenium_improve\\tests\\conftest.py\", line 9, in browser\n    driver = browser.start_browser()\n             ^^^^^^^^^^^^^^^^^^^^^^^\n  File \"D:\\project_selenium_improve\\core\\browser_manager.py\", line 105, in start_browser\n    raise RuntimeError(f\"浏览器启动失败: {str(e)}\")\n"}, "start": 1754706789152, "stop": 1754706828271}], "start": 1754706789152, "stop": 1754706828899}