{"uuid": "af595182-e722-4e28-8e4e-f223f4529d1e", "children": ["893d94ae-f443-4b1a-bb6f-74face1dcd40"], "befores": [{"name": "browser", "status": "broken", "statusDetails": {"message": "RuntimeError: 浏览器启动失败: Message: session not created: probably user data directory is already in use, please specify a unique value for --user-data-dir argument, or don't use --user-data-dir\nStacktrace:\n\tGetHandleVerifier [0x0x122fd23+62915]\n\tGetHandleVerifier [0x0x122fd64+62980]\n\t(No symbol) [0x0x1063e13]\n\t(No symbol) [0x0x10978e8]\n\t(No symbol) [0x0x10931e9]\n\t(No symbol) [0x0x10dce32]\n\t(No symbol) [0x0x10dc74a]\n\t(No symbol) [0x0x10d11d6]\n\t(No symbol) [0x0x10a0833]\n\t(No symbol) [0x0x10a16a4]\n\tGetHandleVerifier [0x0x1498d13+2590131]\n\tGetHandleVerifier [0x0x1493f5a+2570234]\n\tGetHandleVerifier [0x0x12559da+217722]\n\tGetHandleVerifier [0x0x1246048+153832]\n\tGetHandleVerifier [0x0x124c4ad+179533]\n\tGetHandleVerifier [0x0x1237728+94152]\n\tGetHandleVerifier [0x0x12378b2+94546]\n\tGetHandleVerifier [0x0x1222bca+9322]\n\tBaseThreadInitThunk [0x0x75fb5d49+25]\n\tRtlInitializeExceptionChain [0x0x7777d1ab+107]\n\tRtlGetAppContainerNamedObjectPath [0x0x7777d131+561]\n\n", "trace": "  File \"D:\\Python312-32\\Lib\\site-packages\\pluggy\\_callers.py\", line 167, in _multicall\n    teardown.throw(outcome._exception)\n  File \"D:\\Python312-32\\Lib\\site-packages\\pytest_asyncio\\plugin.py\", line 681, in pytest_fixture_setup\n    return (yield)\n            ^^^^^\n  File \"D:\\Python312-32\\Lib\\site-packages\\pluggy\\_callers.py\", line 167, in _multicall\n    teardown.throw(outcome._exception)\n  File \"D:\\Python312-32\\Lib\\site-packages\\_pytest\\setuponly.py\", line 36, in pytest_fixture_setup\n    return (yield)\n            ^^^^^\n  File \"D:\\Python312-32\\Lib\\site-packages\\pluggy\\_callers.py\", line 103, in _multicall\n    res = hook_impl.function(*args)\n          ^^^^^^^^^^^^^^^^^^^^^^^^^\n  File \"D:\\Python312-32\\Lib\\site-packages\\_pytest\\fixtures.py\", line 1140, in pytest_fixture_setup\n    result = call_fixture_func(fixturefunc, request, kwargs)\n             ^^^^^^^^^^^^^^^^^^^^^^^^^^^^^^^^^^^^^^^^^^^^^^^\n  File \"D:\\Python312-32\\Lib\\site-packages\\_pytest\\fixtures.py\", line 891, in call_fixture_func\n    fixture_result = next(generator)\n                     ^^^^^^^^^^^^^^^\n  File \"D:\\project_selenium_improve\\tests\\conftest.py\", line 20, in browser\n    driver = manager.start_browser()\n             ^^^^^^^^^^^^^^^^^^^^^^^\n  File \"D:\\project_selenium_improve\\core\\browser_manager.py\", line 110, in start_browser\n    raise RuntimeError(f\"浏览器启动失败: {str(e)}\")\n"}, "start": 1754980690483, "stop": 1754980714118}], "start": 1754980690483, "stop": 1754980714222}