{"uuid": "7e7c3bc3-da01-4162-869b-ea8707a8cbd6", "children": ["11d9acfb-910b-450e-b537-025ceb4eea97"], "befores": [{"name": "browser", "status": "broken", "statusDetails": {"message": "RuntimeError: 浏览器启动失败: Message: session not created: probably user data directory is already in use, please specify a unique value for --user-data-dir argument, or don't use --user-data-dir\nStacktrace:\n\tGetHandleVerifier [0x0xf4fd23+62915]\n\tGetHandleVerifier [0x0xf4fd64+62980]\n\t(No symbol) [0x0xd83e13]\n\t(No symbol) [0x0xdb78e8]\n\t(No symbol) [0x0xdb31e9]\n\t(No symbol) [0x0xdfce32]\n\t(No symbol) [0x0xdfc74a]\n\t(No symbol) [0x0xdf11d6]\n\t(No symbol) [0x0xdc0833]\n\t(No symbol) [0x0xdc16a4]\n\tGetHandleVerifier [0x0x11b8d13+2590131]\n\tGetHandleVerifier [0x0x11b3f5a+2570234]\n\tGetHandleVerifier [0x0xf759da+217722]\n\tGetHandleVerifier [0x0xf66048+153832]\n\tGetHandleVerifier [0x0xf6c4ad+179533]\n\tGetHandleVerifier [0x0xf57728+94152]\n\tGetHandleVerifier [0x0xf578b2+94546]\n\tGetHandleVerifier [0x0xf42bca+9322]\n\tBaseThreadInitThunk [0x0x752c5d49+25]\n\tRtlInitializeExceptionChain [0x0x771cd1ab+107]\n\tRtlGetAppContainerNamedObjectPath [0x0x771cd131+561]\n\n", "trace": "  File \"D:\\Python312-32\\Lib\\site-packages\\pluggy\\_callers.py\", line 167, in _multicall\n    teardown.throw(outcome._exception)\n  File \"D:\\Python312-32\\Lib\\site-packages\\pytest_asyncio\\plugin.py\", line 681, in pytest_fixture_setup\n    return (yield)\n            ^^^^^\n  File \"D:\\Python312-32\\Lib\\site-packages\\pluggy\\_callers.py\", line 167, in _multicall\n    teardown.throw(outcome._exception)\n  File \"D:\\Python312-32\\Lib\\site-packages\\_pytest\\setuponly.py\", line 36, in pytest_fixture_setup\n    return (yield)\n            ^^^^^\n  File \"D:\\Python312-32\\Lib\\site-packages\\pluggy\\_callers.py\", line 103, in _multicall\n    res = hook_impl.function(*args)\n          ^^^^^^^^^^^^^^^^^^^^^^^^^\n  File \"D:\\Python312-32\\Lib\\site-packages\\_pytest\\fixtures.py\", line 1140, in pytest_fixture_setup\n    result = call_fixture_func(fixturefunc, request, kwargs)\n             ^^^^^^^^^^^^^^^^^^^^^^^^^^^^^^^^^^^^^^^^^^^^^^^\n  File \"D:\\Python312-32\\Lib\\site-packages\\_pytest\\fixtures.py\", line 891, in call_fixture_func\n    fixture_result = next(generator)\n                     ^^^^^^^^^^^^^^^\n  File \"D:\\project_selenium_improve\\tests\\conftest.py\", line 9, in browser\n    driver = browser.start_browser()\n             ^^^^^^^^^^^^^^^^^^^^^^^\n  File \"D:\\project_selenium_improve\\core\\browser_manager.py\", line 105, in start_browser\n    raise RuntimeError(f\"浏览器启动失败: {str(e)}\")\n"}, "start": 1754706789151, "stop": 1754706827854}], "start": 1754706789151, "stop": 1754706828438}