{"uuid": "d289fd34-5db6-4a88-a748-59828ebd602d", "children": ["bd3b3bd8-0643-4ca6-ab42-aec1752605c1"], "befores": [{"name": "browser", "status": "broken", "statusDetails": {"message": "RuntimeError: 浏览器启动失败: Message: session not created: probably user data directory is already in use, please specify a unique value for --user-data-dir argument, or don't use --user-data-dir\nStacktrace:\n\tGetHandleVerifier [0x0xeeba83+63395]\n\tGetHandleVerifier [0x0xeebac4+63460]\n\t(No symbol) [0x0xd32113]\n\t(No symbol) [0x0xd658b8]\n\t(No symbol) [0x0xd611a9]\n\t(No symbol) [0x0xdaae57]\n\t(No symbol) [0x0xdaa74a]\n\t(No symbol) [0x0xd9f1a6]\n\t(No symbol) [0x0xd6e7b2]\n\t(No symbol) [0x0xd6f654]\n\tGetHandleVerifier [0x0x1168883+2672035]\n\tGetHandleVerifier [0x0x1163cba+2652634]\n\tGetHandleVerifier [0x0xf12bca+223466]\n\tGetHandleVerifier [0x0xf02cb8+158168]\n\tGetHandleVerifier [0x0xf0978d+185517]\n\tGetHandleVerifier [0x0xef3b78+96408]\n\tGetHandleVerifier [0x0xef3d02+96802]\n\tGetHandleVerifier [0x0xede90a+9770]\n\tBaseThreadInitThunk [0x0x755e5d49+25]\n\tRtlInitializeExceptionChain [0x0x777cd1ab+107]\n\tRtlGetAppContainerNamedObjectPath [0x0x777cd131+561]\n\n", "trace": "  File \"D:\\Python312-32\\Lib\\site-packages\\pluggy\\_callers.py\", line 167, in _multicall\n    teardown.throw(outcome._exception)\n  File \"D:\\Python312-32\\Lib\\site-packages\\pytest_asyncio\\plugin.py\", line 681, in pytest_fixture_setup\n    return (yield)\n            ^^^^^\n  File \"D:\\Python312-32\\Lib\\site-packages\\pluggy\\_callers.py\", line 167, in _multicall\n    teardown.throw(outcome._exception)\n  File \"D:\\Python312-32\\Lib\\site-packages\\_pytest\\setuponly.py\", line 36, in pytest_fixture_setup\n    return (yield)\n            ^^^^^\n  File \"D:\\Python312-32\\Lib\\site-packages\\pluggy\\_callers.py\", line 103, in _multicall\n    res = hook_impl.function(*args)\n          ^^^^^^^^^^^^^^^^^^^^^^^^^\n  File \"D:\\Python312-32\\Lib\\site-packages\\_pytest\\fixtures.py\", line 1140, in pytest_fixture_setup\n    result = call_fixture_func(fixturefunc, request, kwargs)\n             ^^^^^^^^^^^^^^^^^^^^^^^^^^^^^^^^^^^^^^^^^^^^^^^\n  File \"D:\\Python312-32\\Lib\\site-packages\\_pytest\\fixtures.py\", line 891, in call_fixture_func\n    fixture_result = next(generator)\n                     ^^^^^^^^^^^^^^^\n  File \"D:\\project_selenium_improve\\tests\\conftest.py\", line 7, in browser\n    driver = browser.start_browser()\n             ^^^^^^^^^^^^^^^^^^^^^^^\n  File \"D:\\project_selenium_improve\\core\\browser_manager.py\", line 97, in start_browser\n    raise RuntimeError(f\"浏览器启动失败: {str(e)}\")\n"}, "start": 1754547271390, "stop": 1754547293200}], "start": 1754547271390, "stop": 1754547293347}