[32mINFO    [0m utils.config_manager:config_manager.py:136 Êó•ÂøóÁ≥ªÁªüÂ∑≤ÂàùÂßãÂåñ
[32mINFO    [0m utils.config_manager:config_manager.py:136 ÈÖçÁΩÆÊñá‰ª∂Â∑≤Âä†ËΩΩ:D:\project_selenium_improve\config\config.ini
[1m[31mERROR   [0m core.browser_manager:browser_manager.py:118 ÊµèËßàÂô®ÂêØÂä®Â§±Ë¥•:Message: session not created: probably user data directory is already in use, please specify a unique value for --user-data-dir argument, or don't use --user-data-dir
Stacktrace:
	GetHandleVerifier [0x0xd0ba83+63395]
	GetHandleVerifier [0x0xd0bac4+63460]
	(No symbol) [0x0xb52113]
	(No symbol) [0x0xb858b8]
	(No symbol) [0x0xb811a9]
	(No symbol) [0x0xbcae57]
	(No symbol) [0x0xbca74a]
	(No symbol) [0x0xbbf1a6]
	(No symbol) [0x0xb8e7b2]
	(No symbol) [0x0xb8f654]
	GetHandleVerifier [0x0xf88883+2672035]
	GetHandleVerifier [0x0xf83cba+2652634]
	GetHandleVerifier [0x0xd32bca+223466]
	GetHandleVerifier [0x0xd22cb8+158168]
	GetHandleVerifier [0x0xd2978d+185517]
	GetHandleVerifier [0x0xd13b78+96408]
	GetHandleVerifier [0x0xd13d02+96802]
	GetHandleVerifier [0x0xcfe90a+9770]
	BaseThreadInitThunk [0x0x76ff5d49+25]
	RtlInitializeExceptionChain [0x0x7786d1ab+107]
	RtlGetAppContainerNamedObjectPath [0x0x7786d131+561]
Traceback (most recent call last):
  File "D:\project_selenium_improve\core\browser_manager.py", line 99, in start_browser
    driver = webdriver.Chrome(service=service, options=self.options)
             ^^^^^^^^^^^^^^^^^^^^^^^^^^^^^^^^^^^^^^^^^^^^^^^^^^^^^^^
  File "D:\Python312-32\Lib\site-packages\selenium\webdriver\chrome\webdriver.py", line 45, in __init__
    super().__init__(
  File "D:\Python312-32\Lib\site-packages\selenium\webdriver\chromium\webdriver.py", line 66, in __init__
    super().__init__(command_executor=executor, options=options)
  File "D:\Python312-32\Lib\site-packages\selenium\webdriver\remote\webdriver.py", line 250, in __init__
    self.start_session(capabilities)
  File "D:\Python312-32\Lib\site-packages\selenium\webdriver\remote\webdriver.py", line 342, in start_session
    response = self.execute(Command.NEW_SESSION, caps)["value"]
               ^^^^^^^^^^^^^^^^^^^^^^^^^^^^^^^^^^^^^^^
  File "D:\Python312-32\Lib\site-packages\selenium\webdriver\remote\webdriver.py", line 429, in execute
    self.error_handler.check_response(response)
  File "D:\Python312-32\Lib\site-packages\selenium\webdriver\remote\errorhandler.py", line 232, in check_response
    raise exception_class(message, screen, stacktrace)
selenium.common.exceptions.SessionNotCreatedException: Message: session not created: probably user data directory is already in use, please specify a unique value for --user-data-dir argument, or don't use --user-data-dir
Stacktrace:
	GetHandleVerifier [0x0xd0ba83+63395]
	GetHandleVerifier [0x0xd0bac4+63460]
	(No symbol) [0x0xb52113]
	(No symbol) [0x0xb858b8]
	(No symbol) [0x0xb811a9]
	(No symbol) [0x0xbcae57]
	(No symbol) [0x0xbca74a]
	(No symbol) [0x0xbbf1a6]
	(No symbol) [0x0xb8e7b2]
	(No symbol) [0x0xb8f654]
	GetHandleVerifier [0x0xf88883+2672035]
	GetHandleVerifier [0x0xf83cba+2652634]
	GetHandleVerifier [0x0xd32bca+223466]
	GetHandleVerifier [0x0xd22cb8+158168]
	GetHandleVerifier [0x0xd2978d+185517]
	GetHandleVerifier [0x0xd13b78+96408]
	GetHandleVerifier [0x0xd13d02+96802]
	GetHandleVerifier [0x0xcfe90a+9770]
	BaseThreadInitThunk [0x0x76ff5d49+25]
	RtlInitializeExceptionChain [0x0x7786d1ab+107]
	RtlGetAppContainerNamedObjectPath [0x0x7786d131+561]