[1m[31mERROR   [0m core.browser_manager:browser_manager.py:108 ÊµèËßàÂô®ÂêØÂä®Â§±Ë¥•:Message: session not created: probably user data directory is already in use, please specify a unique value for --user-data-dir argument, or don't use --user-data-dir
Stacktrace:
	GetHandleVerifier [0x0x6afd23+62915]
	GetHandleVerifier [0x0x6afd64+62980]
	(No symbol) [0x0x4e3e13]
	(No symbol) [0x0x5178e8]
	(No symbol) [0x0x5131e9]
	(No symbol) [0x0x55ce32]
	(No symbol) [0x0x55c74a]
	(No symbol) [0x0x5511d6]
	(No symbol) [0x0x520833]
	(No symbol) [0x0x5216a4]
	GetHandleVerifier [0x0x918d13+2590131]
	GetHandleVerifier [0x0x913f5a+2570234]
	GetHandleVerifier [0x0x6d59da+217722]
	GetHandleVerifier [0x0x6c6048+153832]
	GetHandleVerifier [0x0x6cc4ad+179533]
	GetHandleVerifier [0x0x6b7728+94152]
	GetHandleVerifier [0x0x6b78b2+94546]
	GetHandleVerifier [0x0x6a2bca+9322]
	BaseThreadInitThunk [0x0x75fb5d49+25]
	RtlInitializeExceptionChain [0x0x7777d1ab+107]
	RtlGetAppContainerNamedObjectPath [0x0x7777d131+561]
Traceback (most recent call last):
  File "D:\project_selenium_improve\core\browser_manager.py", line 90, in start_browser
    driver = webdriver.Chrome(service=service, options=self.options)
             ^^^^^^^^^^^^^^^^^^^^^^^^^^^^^^^^^^^^^^^^^^^^^^^^^^^^^^^
  File "D:\Python312-32\Lib\site-packages\selenium\webdriver\chrome\webdriver.py", line 45, in __init__
    super().__init__(
  File "D:\Python312-32\Lib\site-packages\selenium\webdriver\chromium\webdriver.py", line 66, in __init__
    super().__init__(command_executor=executor, options=options)
  File "D:\Python312-32\Lib\site-packages\selenium\webdriver\remote\webdriver.py", line 250, in __init__
    self.start_session(capabilities)
  File "D:\Python312-32\Lib\site-packages\selenium\webdriver\remote\webdriver.py", line 342, in start_session
    response = self.execute(Command.NEW_SESSION, caps)["value"]
               ^^^^^^^^^^^^^^^^^^^^^^^^^^^^^^^^^^^^^^^
  File "D:\Python312-32\Lib\site-packages\selenium\webdriver\remote\webdriver.py", line 429, in execute
    self.error_handler.check_response(response)
  File "D:\Python312-32\Lib\site-packages\selenium\webdriver\remote\errorhandler.py", line 232, in check_response
    raise exception_class(message, screen, stacktrace)
selenium.common.exceptions.SessionNotCreatedException: Message: session not created: probably user data directory is already in use, please specify a unique value for --user-data-dir argument, or don't use --user-data-dir
Stacktrace:
	GetHandleVerifier [0x0x6afd23+62915]
	GetHandleVerifier [0x0x6afd64+62980]
	(No symbol) [0x0x4e3e13]
	(No symbol) [0x0x5178e8]
	(No symbol) [0x0x5131e9]
	(No symbol) [0x0x55ce32]
	(No symbol) [0x0x55c74a]
	(No symbol) [0x0x5511d6]
	(No symbol) [0x0x520833]
	(No symbol) [0x0x5216a4]
	GetHandleVerifier [0x0x918d13+2590131]
	GetHandleVerifier [0x0x913f5a+2570234]
	GetHandleVerifier [0x0x6d59da+217722]
	GetHandleVerifier [0x0x6c6048+153832]
	GetHandleVerifier [0x0x6cc4ad+179533]
	GetHandleVerifier [0x0x6b7728+94152]
	GetHandleVerifier [0x0x6b78b2+94546]
	GetHandleVerifier [0x0x6a2bca+9322]
	BaseThreadInitThunk [0x0x75fb5d49+25]
	RtlInitializeExceptionChain [0x0x7777d1ab+107]
	RtlGetAppContainerNamedObjectPath [0x0x7777d131+561]